<?xml version="1.0" encoding="UTF-8"?>
<!-- Generated by org.testng.reporters.JUnitReportReporter -->
<testsuite hostname="Taras-PC" failures="1" tests="1" name="com.epam.lab.github.tests.TestGitHub" time="19.373" errors="0" timestamp="05 черв. 2018 15:20:02 GMT" skipped="0">
  <testcase classname="com.epam.lab.github.tests.TestGitHub" name="logIn" time="19.373">
    <failure message="The following asserts failed:
	expected [10] but found [9],
	expected [10] but found [9]" type="java.lang.AssertionError">
      <![CDATA[java.lang.AssertionError: The following asserts failed:expected [10] but found [9],expected [10] but found [9]at org.testng.asserts.SoftAssert.assertAll(SoftAssert.java:43)at com.epam.lab.github.tests.TestGitHub.logIn(TestGitHub.java:62)at java.base/jdk.internal.reflect.NativeMethodAccessorImpl.invoke0(Native Method)at java.base/jdk.internal.reflect.NativeMethodAccessorImpl.invoke(NativeMethodAccessorImpl.java:62)at java.base/jdk.internal.reflect.DelegatingMethodAccessorImpl.invoke(DelegatingMethodAccessorImpl.java:43)at java.base/java.lang.reflect.Method.invoke(Method.java:564)at org.testng.internal.MethodInvocationHelper.invokeMethod(MethodInvocationHelper.java:124)at org.testng.internal.Invoker.invokeMethod(Invoker.java:571)at org.testng.internal.Invoker.invokeTestMethod(Invoker.java:707)at org.testng.internal.Invoker.invokeTestMethods(Invoker.java:979)at org.testng.internal.TestMethodWorker.invokeTestMethods(TestMethodWorker.java:125)at org.testng.internal.TestMethodWorker.run(TestMethodWorker.java:109)at org.testng.TestRunner.privateRun(TestRunner.java:648)at org.testng.TestRunner.run(TestRunner.java:505)at org.testng.SuiteRunner.runTest(SuiteRunner.java:455)at org.testng.SuiteRunner.runSequentially(SuiteRunner.java:450)at org.testng.SuiteRunner.privateRun(SuiteRunner.java:415)at org.testng.SuiteRunner.run(SuiteRunner.java:364)at org.testng.SuiteRunnerWorker.runSuite(SuiteRunnerWorker.java:52)at org.testng.SuiteRunnerWorker.run(SuiteRunnerWorker.java:84)at org.testng.TestNG.runSuitesSequentially(TestNG.java:1187)at org.testng.TestNG.runSuitesLocally(TestNG.java:1116)at org.testng.TestNG.runSuites(TestNG.java:1028)at org.testng.TestNG.run(TestNG.java:996)at org.apache.maven.surefire.testng.TestNGExecutor.run(TestNGExecutor.java:281)at org.apache.maven.surefire.testng.TestNGXmlTestSuite.execute(TestNGXmlTestSuite.java:75)at org.apache.maven.surefire.testng.TestNGProvider.invoke(TestNGProvider.java:121)at org.apache.maven.surefire.booter.ForkedBooter.invokeProviderInSameClassLoader(ForkedBooter.java:290)at org.apache.maven.surefire.booter.ForkedBooter.runSuitesInProcess(ForkedBooter.java:242)at org.apache.maven.surefire.booter.ForkedBooter.main(ForkedBooter.java:121)]]>
    </failure>
  </testcase> <!-- logIn -->
</testsuite> <!-- com.epam.lab.github.tests.TestGitHub -->
